Workbook

Sheet Instructions
A1: User Acceptance Testing — PWMS
A2: IRPD section · Delegation Reports · International Resolutions · International Agreements
B4: What this workbook is: the results side of the printable acceptance form. The form and its PDF remain the record that is signed; this workbook is where the section's testers record what they found, and where the results are rolled up.
B6: Generated from UAT Form.html. The form is the source of truth for the scenarios, so change the form and rebuild rather than editing the scenario rows here.
A9: How to use it
B10: • On the Results sheet, type each tester's name at the top of their own column (columns H onward). One column per person.
B11: • Work down the rows and record your result in your own column — choose P, F, B or N from the drop-down. Leave a cell blank if you have not tested that scenario yet.
B12: • The Scenarios sheet has the full steps and expected result for each row: read it there, then record on Results. Expected behaviour lists the deliberate behaviours that must not be logged as defects.
B13: • Where a result is F or B, add a row to the Defect log and give the scenario's ID in its Scenario column, so the defect and the scenario tie together.
B14: • The Summary sheet counts everything as you type and tells you whether the acceptance criteria are met. Complete the Sign-off sheet when the section is ready to decide.
A16: Result key
B17: P | C17: Pass: as expected
B18: F | C18: Fail: not as expected
B19: B | C19: Blocked: could not be carried out
B20: N | C20: Not applicable
A22: Severity — grade every defect you log
B23: S1 — Blocking | C23: The section cannot carry out real work, or data is lost or corrupted.
B24: S2 — Major | C24: A core task gives the wrong result and there is no acceptable workaround.
B25: S3 — Minor | C25: The task works but with an awkward workaround, or a field, label or figure is wrong.
B26: S4 — Cosmetic | C26: Appearance or wording only; nothing about the work changes.
A28: Test details
B29: Environment (URL)
B30: Build / version tested
B31: Test round (1st / re-test / final)
B32: Date(s) of testing

Sheet Scenarios
A1: Scenarios
A2: The full steps and acceptance criteria behind each row of Results
A3: ID | B3: Area | C3: Critical | D3: What to do | E3: Expected result (acceptance criterion)
A4: A1 | B4: A — Access and sign-in | C4: Yes | D4: Open the environment and sign in with your normal Parliament directory account. | E4: You reach the Dashboard. No separate PWMS password is asked for.
A5: A2 | B5: A — Access and sign-in | D5: Read the Dashboard: the four figures, then the four work lists. | E5: The figures are Total workflows, Assigned to you, Due in 7 days and Overdue. The lists are Assigned to you, Due soon, Overdue and Awaiting your committees, and the records in them are ones you recognise as yours.
A6: A3 | B6: A — Access and sign-in | C6: Yes | D6: Open the three instrument registers and the cross-instrument Workflows list. | E6: You see the records you are entitled to and no others. A record you may not open does not appear in any list, or in the report builder's filter lists.
A7: A4 | B7: A — Access and sign-in | D7: Open Workflows → Create a workflow, then each register's New button. | E7: New Report, New Resolution and New Agreement are all offered to you.
A8: B1 | B8: B — Reading and monitoring a record | D8: Open a delegation report's Overview tab. | E8: It states the title, owner, who it is assigned to, its stage, priority and due date, its description, the engagement dates and location, the report document link — and carries the BR03 updates card.
A9: B2 | B9: B — Reading and monitoring a record | D9: Open the Progress tab. | E9: A completion percentage, the stage sequence with the current stage marked, and a journey naming who moved the record, when and with what comment.
A10: B3 | B10: B — Reading and monitoring a record | D10: Change the record's title, save, then open its Timeline tab. | E10: The edit appears in the merged history with your name and the time, alongside every stage change. Nothing on the record changes without appearing here.
A11: B4 | B11: B — Reading and monitoring a record | D11: Find a record whose deadline has passed while it is still open (set a past deadline on a training record if needed). | E11: It is flagged overdue on the record and in the register. A record in a final stage is never shown as overdue.
A12: C1 | B12: C — Capturing a delegation report | C12: Yes | D12: New Report. Complete the title, description, deadline and priority, then the engagement name, country, city, start and end dates and the report document link. Create report. | E12: Confirmed. The record is given a DR-<year>-<sequence> reference by the system and starts at Awaiting PGIR approval .
A13: C2 | B13: C — Capturing a delegation report | D13: Try to save a start date in the future. Then try an end date earlier than the start date. | E13: Both are refused, with the reason given on the field. Neither is saved.
A14: C3 | B14: C — Capturing a delegation report | D14: Add a Parliamentary Delegation Member and a Support Official, each with the role they held. Then take one of them off the delegation. | E14: Both appear with their type and role. The person taken off stays listed, struck through, showing who removed them and when.
A15: C4 | B15: C — Capturing a delegation report | D15: On the report's Related tab, use Resolutions adopted → Add Resolution to add a resolution (title, number, adoption date). | E15: The resolution is created as an international resolution, owned by you and linked to this report, and is listed on the card.
A16: C5 | B16: C — Capturing a delegation report | D16: Try to capture a second resolution using a number that is already in use. | E16: Refused, with a message that the resolution number already exists.
A17: D1 | B17: D — Capturing a resolution and an agreement | D17: New Resolution, with no parent report: give the number, title, adoption date, responsible group and resolution text. | E17: Created successfully at the stage Captured . You supply the resolution number; the system does not generate it.
A18: D2 | B18: D — Capturing a resolution and an agreement | D18: New Agreement: set the agreement type (Section 231(2) or 231(3)), the ATC tabling date, the submitting department and the referral committees. | E18: Created successfully, starting at Agreement Tabled – referred to Committee — not at the first stage printed on the diagram.
A19: D3 | B19: D — Capturing a resolution and an agreement | D19: As the responsible minister, try to link a person who does not hold a current executive appointment. Then record that person's name in the responsible-minister name field instead. | E19: The link is refused, with the reason stated. The name field saves, so an agreement signed by a former minister can still be recorded accurately.
A20: E1 | B20: E — Moving a record on, and the ATC publication | C20: Yes | D20: On a report at Tabled and referred to Committee with no ATC update recorded, open Status → Close – House approved. | E20: The confirmation page refuses it, headed This transition cannot be taken yet , and states that an ATC update published event is required. The confirm button is not available.
A21: E2 | B21: E — Moving a record on, and the ATC publication | C21: Yes | D21: On the same report's Overview tab, use BR03 updates → Add update. Give the date and any one ATC detail (reference, publication date, page or document link). Record update. | E21: Confirmed, and PWMS states the report may now be closed from the Status menu. The update is listed in the report's update history and the ATC reference shows on Overview.
A22: E3 | B22: E — Moving a record on, and the ATC publication | C22: Yes | D22: Now open Status → Close – House approved, add a comment, and confirm the change. | E22: The move is accepted, and you land on the Timeline showing the move, your name and your comment. The record shows as closed and stops being flagged overdue.
A23: E4 | B23: E — Moving a record on, and the ATC publication | D23: Confirm with the administrator (or a colleague in a committee the record was referred to) what that committee can do on a record while the referral is open. | E23: The committee can read and edit the record, but is not offered the Status menu — moving a record on remains the owning section's job.
A24: F1 | B24: F — Referrals | D24: On a record, open the Referrals tab → Add Referral. Choose a committee, set the response due date, and say what the committee should consider. Send referral. | E24: Confirmed. The referral is listed as open with its due date, and the committee's members are notified (bell, and email where configured).
A25: F2 | B25: F — Referrals | C25: Yes | D25: With the committee (or the administrator), confirm what access the referral gave them to the record. | E25: The committee can read and edit the record while the referral is open, and keeps view after it closes. It is not given the right to move the record on.
A26: F3 | B26: F — Referrals | D26: Record an answer to the referral (a response document link and notes). Then raise a second referral and withdraw it, giving a reason. | E26: The first is recorded as answered, with who answered and when. The second is recorded as withdrawn, with the reason and who withdrew it.
A27: F4 | B27: F — Referrals | D27: With the administrator, check that a referral due within 24 hours raises a reminder (needs the background worker and mail service to be configured). | E27: A reminder is sent to the committee and recorded against the referral. Mark N/A if email is not yet configured for the environment.
A28: G1 | B28: G — Documents | D28: Attachments tab → Add attachment. Browse your sites and libraries and attach a document that already exists in SharePoint. | E28: The document is listed against the record with its type, folder, who attached it and when.
A29: G2 | B29: G — Documents | D29: In the same panel, upload a new file into a folder, choosing an attachment type first. | E29: Confirmed. The file is placed in SharePoint and attached to the record in one step.
A30: G3 | B30: G — Documents | C30: Yes | D30: Select an attached document's name to open it. | E30: It opens in a new tab. You are not asked to sign in to SharePoint.
A31: G4 | B31: G — Documents | D31: Open a document's Versions panel. Then upload a revised copy using the same file name into the same folder. | E31: The version history lists the versions with a download for each. The revised copy is recorded as a new version of the same document, not as a second document.
A32: G5 | B32: G — Documents | D32: Detach an attached document, confirming the prompt. | E32: The link is removed from the record. The file and its versions remain in SharePoint, and the detachment is recorded on the record's history.
A33: H1 | B33: H — Notes | D33: Notes tab → Add Note, write a note and save it. | E33: The note is listed with your name and the date and time it was recorded.
A34: H2 | B34: H — Notes | D34: Ask a colleague to try to edit or delete the note you just wrote. | E34: They cannot change your note; they can add their own instead. A note belongs to its author.
A35: I1 | B35: I — Reporting, exports and sharing | C35: Yes | D35: Reports → Report builder. Filter by workflow type, state, period and overdue only, then run the report. | E35: The preview shows the record count, the four summary figures, and the matching register. It contains only records you are permitted to open — and the filter lists offer no values from records you cannot see.
A36: I2 | B36: I — Reporting, exports and sharing | D36: Export the same report as Excel, PDF, Web page and CSV. | E36: All four download and open. The CSV carries the register only; the other three carry the summary, the breakdowns, the register, the activity and the referrals, whichever report type was selected.
A37: I3 | B37: I — Reporting, exports and sharing | D37: Open a record and use its Document menu to produce a PDF. | E37: A formal document for that one instrument downloads, showing its facts, people, referrals, documents and history.
A38: I4 | B38: I — Reporting, exports and sharing | D38: On the report preview, select Share . Give it a name, an expiry and recipient addresses, then create the link. Open the link in a private window. | E38: The recipient must sign in to PWMS, then sees the report read-only showing the creator's figures. The Share button is not offered to them.
A39: I5 | B39: I — Reporting, exports and sharing | D39: Open the alert bell. Open one alert. Then use Mark all read. | E39: The bell shows the unread count. Opening an alert marks it read and takes you to the record it concerns. Mark all read clears the rest — merely viewing the alerts page marks nothing read.
A40: J1 | B40: J — Records and accountability | C40: Yes | D40: Move a record through a transition, then read its Timeline and its Progress tab. | E40: The move, the person who made it, the time and the comment are all recorded, and the record's stage and progress have changed accordingly. Nothing is recorded anonymously.
...

Sheet Results
A1: Results — one column per tester
A3: Environment (URL)
A4: Build / version tested
A5: Test round (1st / re-test / final)
A6: Date(s) of testing
A8: ID | B8: Area | C8: Critical | D8: Failed by | E8: Blocked by | F8: Tested | G8: Status | H8: Tester 1 | I8: Tester 2 | J8: Tester 3 | K8: Tester 4 | L8: Tester 5 | M8: Tester 6 | N8: Tester 7 | O8: Tester 8
A9: ← each tester types their name at the top of their own column
A10: A1 | B10: A — Access and sign-in | C10: Yes | D10: =COUNTIF($H10:$O10,"F") | E10: =COUNTIF($H10:$O10,"B") | F10: =COUNTIF($H10:$O10,"P")+COUNTIF($H10:$O10,"F")+COUNTIF($H10:$O10,"B") | G10: =IF(D10>0,"FAILED",IF(E10>0,"BLOCKED",IF(F10>0,"OK","Not tested")))
A11: A2 | B11: A — Access and sign-in | D11: =COUNTIF($H11:$O11,"F") | E11: =COUNTIF($H11:$O11,"B") | F11: =COUNTIF($H11:$O11,"P")+COUNTIF($H11:$O11,"F")+COUNTIF($H11:$O11,"B") | G11: =IF(D11>0,"FAILED",IF(E11>0,"BLOCKED",IF(F11>0,"OK","Not tested")))
A12: A3 | B12: A — Access and sign-in | C12: Yes | D12: =COUNTIF($H12:$O12,"F") | E12: =COUNTIF($H12:$O12,"B") | F12: =COUNTIF($H12:$O12,"P")+COUNTIF($H12:$O12,"F")+COUNTIF($H12:$O12,"B") | G12: =IF(D12>0,"FAILED",IF(E12>0,"BLOCKED",IF(F12>0,"OK","Not tested")))
A13: A4 | B13: A — Access and sign-in | D13: =COUNTIF($H13:$O13,"F") | E13: =COUNTIF($H13:$O13,"B") | F13: =COUNTIF($H13:$O13,"P")+COUNTIF($H13:$O13,"F")+COUNTIF($H13:$O13,"B") | G13: =IF(D13>0,"FAILED",IF(E13>0,"BLOCKED",IF(F13>0,"OK","Not tested")))
A14: B1 | B14: B — Reading and monitoring a record | D14: =COUNTIF($H14:$O14,"F") | E14: =COUNTIF($H14:$O14,"B") | F14: =COUNTIF($H14:$O14,"P")+COUNTIF($H14:$O14,"F")+COUNTIF($H14:$O14,"B") | G14: =IF(D14>0,"FAILED",IF(E14>0,"BLOCKED",IF(F14>0,"OK","Not tested")))
A15: B2 | B15: B — Reading and monitoring a record | D15: =COUNTIF($H15:$O15,"F") | E15: =COUNTIF($H15:$O15,"B") | F15: =COUNTIF($H15:$O15,"P")+COUNTIF($H15:$O15,"F")+COUNTIF($H15:$O15,"B") | G15: =IF(D15>0,"FAILED",IF(E15>0,"BLOCKED",IF(F15>0,"OK","Not tested")))
A16: B3 | B16: B — Reading and monitoring a record | D16: =COUNTIF($H16:$O16,"F") | E16: =COUNTIF($H16:$O16,"B") | F16: =COUNTIF($H16:$O16,"P")+COUNTIF($H16:$O16,"F")+COUNTIF($H16:$O16,"B") | G16: =IF(D16>0,"FAILED",IF(E16>0,"BLOCKED",IF(F16>0,"OK","Not tested")))
A17: B4 | B17: B — Reading and monitoring a record | D17: =COUNTIF($H17:$O17,"F") | E17: =COUNTIF($H17:$O17,"B") | F17: =COUNTIF($H17:$O17,"P")+COUNTIF($H17:$O17,"F")+COUNTIF($H17:$O17,"B") | G17: =IF(D17>0,"FAILED",IF(E17>0,"BLOCKED",IF(F17>0,"OK","Not tested")))
A18: C1 | B18: C — Capturing a delegation report | C18: Yes | D18: =COUNTIF($H18:$O18,"F") | E18: =COUNTIF($H18:$O18,"B") | F18: =COUNTIF($H18:$O18,"P")+COUNTIF($H18:$O18,"F")+COUNTIF($H18:$O18,"B") | G18: =IF(D18>0,"FAILED",IF(E18>0,"BLOCKED",IF(F18>0,"OK","Not tested")))
A19: C2 | B19: C — Capturing a delegation report | D19: =COUNTIF($H19:$O19,"F") | E19: =COUNTIF($H19:$O19,"B") | F19: =COUNTIF($H19:$O19,"P")+COUNTIF($H19:$O19,"F")+COUNTIF($H19:$O19,"B") | G19: =IF(D19>0,"FAILED",IF(E19>0,"BLOCKED",IF(F19>0,"OK","Not tested")))
A20: C3 | B20: C — Capturing a delegation report | D20: =COUNTIF($H20:$O20,"F") | E20: =COUNTIF($H20:$O20,"B") | F20: =COUNTIF($H20:$O20,"P")+COUNTIF($H20:$O20,"F")+COUNTIF($H20:$O20,"B") | G20: =IF(D20>0,"FAILED",IF(E20>0,"BLOCKED",IF(F20>0,"OK","Not tested")))
A21: C4 | B21: C — Capturing a delegation report | D21: =COUNTIF($H21:$O21,"F") | E21: =COUNTIF($H21:$O21,"B") | F21: =COUNTIF($H21:$O21,"P")+COUNTIF($H21:$O21,"F")+COUNTIF($H21:$O21,"B") | G21: =IF(D21>0,"FAILED",IF(E21>0,"BLOCKED",IF(F21>0,"OK","Not tested")))
A22: C5 | B22: C — Capturing a delegation report | D22: =COUNTIF($H22:$O22,"F") | E22: =COUNTIF($H22:$O22,"B") | F22: =COUNTIF($H22:$O22,"P")+COUNTIF($H22:$O22,"F")+COUNTIF($H22:$O22,"B") | G22: =IF(D22>0,"FAILED",IF(E22>0,"BLOCKED",IF(F22>0,"OK","Not tested")))
A23: D1 | B23: D — Capturing a resolution and an agreement | D23: =COUNTIF($H23:$O23,"F") | E23: =COUNTIF($H23:$O23,"B") | F23: =COUNTIF($H23:$O23,"P")+COUNTIF($H23:$O23,"F")+COUNTIF($H23:$O23,"B") | G23: =IF(D23>0,"FAILED",IF(E23>0,"BLOCKED",IF(F23>0,"OK","Not tested")))
A24: D2 | B24: D — Capturing a resolution and an agreement | D24: =COUNTIF($H24:$O24,"F") | E24: =COUNTIF($H24:$O24,"B") | F24: =COUNTIF($H24:$O24,"P")+COUNTIF($H24:$O24,"F")+COUNTIF($H24:$O24,"B") | G24: =IF(D24>0,"FAILED",IF(E24>0,"BLOCKED",IF(F24>0,"OK","Not tested")))
A25: D3 | B25: D — Capturing a resolution and an agreement | D25: =COUNTIF($H25:$O25,"F") | E25: =COUNTIF($H25:$O25,"B") | F25: =COUNTIF($H25:$O25,"P")+COUNTIF($H25:$O25,"F")+COUNTIF($H25:$O25,"B") | G25: =IF(D25>0,"FAILED",IF(E25>0,"BLOCKED",IF(F25>0,"OK","Not tested")))
A26: E1 | B26: E — Moving a record on, and the ATC publication | C26: Yes | D26: =COUNTIF($H26:$O26,"F") | E26: =COUNTIF($H26:$O26,"B") | F26: =COUNTIF($H26:$O26,"P")+COUNTIF($H26:$O26,"F")+COUNTIF($H26:$O26,"B") | G26: =IF(D26>0,"FAILED",IF(E26>0,"BLOCKED",IF(F26>0,"OK","Not tested")))
A27: E2 | B27: E — Moving a record on, and the ATC publication | C27: Yes | D27: =COUNTIF($H27:$O27,"F") | E27: =COUNTIF($H27:$O27,"B") | F27: =COUNTIF($H27:$O27,"P")+COUNTIF($H27:$O27,"F")+COUNTIF($H27:$O27,"B") | G27: =IF(D27>0,"FAILED",IF(E27>0,"BLOCKED",IF(F27>0,"OK","Not tested")))
A28: E3 | B28: E — Moving a record on, and the ATC publication | C28: Yes | D28: =COUNTIF($H28:$O28,"F") | E28: =COUNTIF($H28:$O28,"B") | F28: =COUNTIF($H28:$O28,"P")+COUNTIF($H28:$O28,"F")+COUNTIF($H28:$O28,"B") | G28: =IF(D28>0,"FAILED",IF(E28>0,"BLOCKED",IF(F28>0,"OK","Not tested")))
A29: E4 | B29: E — Moving a record on, and the ATC publication | D29: =COUNTIF($H29:$O29,"F") | E29: =COUNTIF($H29:$O29,"B") | F29: =COUNTIF($H29:$O29,"P")+COUNTIF($H29:$O29,"F")+COUNTIF($H29:$O29,"B") | G29: =IF(D29>0,"FAILED",IF(E29>0,"BLOCKED",IF(F29>0,"OK","Not tested")))
A30: F1 | B30: F — Referrals | D30: =COUNTIF($H30:$O30,"F") | E30: =COUNTIF($H30:$O30,"B") | F30: =COUNTIF($H30:$O30,"P")+COUNTIF($H30:$O30,"F")+COUNTIF($H30:$O30,"B") | G30: =IF(D30>0,"FAILED",IF(E30>0,"BLOCKED",IF(F30>0,"OK","Not tested")))
A31: F2 | B31: F — Referrals | C31: Yes | D31: =COUNTIF($H31:$O31,"F") | E31: =COUNTIF($H31:$O31,"B") | F31: =COUNTIF($H31:$O31,"P")+COUNTIF($H31:$O31,"F")+COUNTIF($H31:$O31,"B") | G31: =IF(D31>0,"FAILED",IF(E31>0,"BLOCKED",IF(F31>0,"OK","Not tested")))
A32: F3 | B32: F — Referrals | D32: =COUNTIF($H32:$O32,"F") | E32: =COUNTIF($H32:$O32,"B") | F32: =COUNTIF($H32:$O32,"P")+COUNTIF($H32:$O32,"F")+COUNTIF($H32:$O32,"B") | G32: =IF(D32>0,"FAILED",IF(E32>0,"BLOCKED",IF(F32>0,"OK","Not tested")))
A33: F4 | B33: F — Referrals | D33: =COUNTIF($H33:$O33,"F") | E33: =COUNTIF($H33:$O33,"B") | F33: =COUNTIF($H33:$O33,"P")+COUNTIF($H33:$O33,"F")+COUNTIF($H33:$O33,"B") | G33: =IF(D33>0,"FAILED",IF(E33>0,"BLOCKED",IF(F33>0,"OK","Not tested")))
A34: G1 | B34: G — Documents | D34: =COUNTIF($H34:$O34,"F") | E34: =COUNTIF($H34:$O34,"B") | F34: =COUNTIF($H34:$O34,"P")+COUNTIF($H34:$O34,"F")+COUNTIF($H34:$O34,"B") | G34: =IF(D34>0,"FAILED",IF(E34>0,"BLOCKED",IF(F34>0,"OK","Not tested")))
A35: G2 | B35: G — Documents | D35: =COUNTIF($H35:$O35,"F") | E35: =COUNTIF($H35:$O35,"B") | F35: =COUNTIF($H35:$O35,"P")+COUNTIF($H35:$O35,"F")+COUNTIF($H35:$O35,"B") | G35: =IF(D35>0,"FAILED",IF(E35>0,"BLOCKED",IF(F35>0,"OK","Not tested")))
A36: G3 | B36: G — Documents | C36: Yes | D36: =COUNTIF($H36:$O36,"F") | E36: =COUNTIF($H36:$O36,"B") | F36: =COUNTIF($H36:$O36,"P")+COUNTIF($H36:$O36,"F")+COUNTIF($H36:$O36,"B") | G36: =IF(D36>0,"FAILED",IF(E36>0,"BLOCKED",IF(F36>0,"OK","Not tested")))
A37: G4 | B37: G — Documents | D37: =COUNTIF($H37:$O37,"F") | E37: =COUNTIF($H37:$O37,"B") | F37: =COUNTIF($H37:$O37,"P")+COUNTIF($H37:$O37,"F")+COUNTIF($H37:$O37,"B") | G37: =IF(D37>0,"FAILED",IF(E37>0,"BLOCKED",IF(F37>0,"OK","Not tested")))
A38: G5 | B38: G — Documents | D38: =COUNTIF($H38:$O38,"F") | E38: =COUNTIF($H38:$O38,"B") | F38: =COUNTIF($H38:$O38,"P")+COUNTIF($H38:$O38,"F")+COUNTIF($H38:$O38,"B") | G38: =IF(D38>0,"FAILED",IF(E38>0,"BLOCKED",IF(F38>0,"OK","Not tested")))
A39: H1 | B39: H — Notes | D39: =COUNTIF($H39:$O39,"F") | E39: =COUNTIF($H39:$O39,"B") | F39: =COUNTIF($H39:$O39,"P")+COUNTIF($H39:$O39,"F")+COUNTIF($H39:$O39,"B") | G39: =IF(D39>0,"FAILED",IF(E39>0,"BLOCKED",IF(F39>0,"OK","Not tested")))
A40: H2 | B40: H — Notes | D40: =COUNTIF($H40:$O40,"F") | E40: =COUNTIF($H40:$O40,"B") | F40: =COUNTIF($H40:$O40,"P")+COUNTIF($H40:$O40,"F")+COUNTIF($H40:$O40,"B") | G40: =IF(D40>0,"FAILED",IF(E40>0,"BLOCKED",IF(F40>0,"OK","Not tested")))
A41: I1 | B41: I — Reporting, exports and sharing | C41: Yes | D41: =COUNTIF($H41:$O41,"F") | E41: =COUNTIF($H41:$O41,"B") | F41: =COUNTIF($H41:$O41,"P")+COUNTIF($H41:$O41,"F")+COUNTIF($H41:$O41,"B") | G41: =IF(D41>0,"FAILED",IF(E41>0,"BLOCKED",IF(F41>0,"OK","Not tested")))
A42: I2 | B42: I — Reporting, exports and sharing | D42: =COUNTIF($H42:$O42,"F") | E42: =COUNTIF($H42:$O42,"B") | F42: =COUNTIF($H42:$O42,"P")+COUNTIF($H42:$O42,"F")+COUNTIF($H42:$O42,"B") | G42: =IF(D42>0,"FAILED",IF(E42>0,"BLOCKED",IF(F42>0,"OK","Not tested")))
...

Sheet Defect log
A1: Defect log
A2: One row per defect. Give the scenario's ID in column B so the two tie together.
A3: Defect ID | B3: Scenario | C3: Area | D3: Severity | E3: What happened, and the steps that produced it | F3: Reported to / date | G3: Status

Sheet Summary
A1: Summary — are the acceptance criteria met?
A2: Counted live from Results and the Defect log as the section types
A4: By tester
B5: Tester | C5: Passed | D5: Failed | E5: Blocked | F5: N/A | G5: Tested
B6: =IF(Results!H9="","(unnamed)",Results!H9) | C6: =COUNTIF(Results!H$10:H$47,"P") | D6: =COUNTIF(Results!H$10:H$47,"F") | E6: =COUNTIF(Results!H$10:H$47,"B") | F6: =COUNTIF(Results!H$10:H$47,"N") | G6: =SUM(C6:F6)
B7: =IF(Results!I9="","(unnamed)",Results!I9) | C7: =COUNTIF(Results!I$10:I$47,"P") | D7: =COUNTIF(Results!I$10:I$47,"F") | E7: =COUNTIF(Results!I$10:I$47,"B") | F7: =COUNTIF(Results!I$10:I$47,"N") | G7: =SUM(C7:F7)
B8: =IF(Results!J9="","(unnamed)",Results!J9) | C8: =COUNTIF(Results!J$10:J$47,"P") | D8: =COUNTIF(Results!J$10:J$47,"F") | E8: =COUNTIF(Results!J$10:J$47,"B") | F8: =COUNTIF(Results!J$10:J$47,"N") | G8: =SUM(C8:F8)
B9: =IF(Results!K9="","(unnamed)",Results!K9) | C9: =COUNTIF(Results!K$10:K$47,"P") | D9: =COUNTIF(Results!K$10:K$47,"F") | E9: =COUNTIF(Results!K$10:K$47,"B") | F9: =COUNTIF(Results!K$10:K$47,"N") | G9: =SUM(C9:F9)
B10: =IF(Results!L9="","(unnamed)",Results!L9) | C10: =COUNTIF(Results!L$10:L$47,"P") | D10: =COUNTIF(Results!L$10:L$47,"F") | E10: =COUNTIF(Results!L$10:L$47,"B") | F10: =COUNTIF(Results!L$10:L$47,"N") | G10: =SUM(C10:F10)
B11: =IF(Results!M9="","(unnamed)",Results!M9) | C11: =COUNTIF(Results!M$10:M$47,"P") | D11: =COUNTIF(Results!M$10:M$47,"F") | E11: =COUNTIF(Results!M$10:M$47,"B") | F11: =COUNTIF(Results!M$10:M$47,"N") | G11: =SUM(C11:F11)
B12: =IF(Results!N9="","(unnamed)",Results!N9) | C12: =COUNTIF(Results!N$10:N$47,"P") | D12: =COUNTIF(Results!N$10:N$47,"F") | E12: =COUNTIF(Results!N$10:N$47,"B") | F12: =COUNTIF(Results!N$10:N$47,"N") | G12: =SUM(C12:F12)
B13: =IF(Results!O9="","(unnamed)",Results!O9) | C13: =COUNTIF(Results!O$10:O$47,"P") | D13: =COUNTIF(Results!O$10:O$47,"F") | E13: =COUNTIF(Results!O$10:O$47,"B") | F13: =COUNTIF(Results!O$10:O$47,"N") | G13: =SUM(C13:F13)
A15: By scenario
B16: Status | C16: Count
B17: FAILED | C17: =COUNTIF(Results!G10:G47,"FAILED")
B18: BLOCKED | C18: =COUNTIF(Results!G10:G47,"BLOCKED")
B19: OK | C19: =COUNTIF(Results!G10:G47,"OK")
B20: Not tested | C20: =COUNTIF(Results!G10:G47,"Not tested")
A22: Critical scenarios — all must pass
B23: Critical scenarios in total | C23: =COUNTIF(Results!C10:C47,"Yes")
B24: Failed by at least one tester | C24: =COUNTIFS(Results!C10:C47,"Yes",Results!D10:D47,">0")
B25: Blocked for at least one tester | C25: =COUNTIFS(Results!C10:C47,"Yes",Results!E10:E47,">0")
B26: Not tested yet | C26: =COUNTIFS(Results!C10:C47,"Yes",Results!F10:F47,"=0")
A28: Open defects by severity
B29: S1 | C29: =COUNTIFS('Defect log'!$D$4:$D$43,"S1",'Defect log'!$G$4:$G$43,"Open")
B30: S2 | C30: =COUNTIFS('Defect log'!$D$4:$D$43,"S2",'Defect log'!$G$4:$G$43,"Open")
B31: S3 | C31: =COUNTIFS('Defect log'!$D$4:$D$43,"S3",'Defect log'!$G$4:$G$43,"Open")
B32: S4 | C32: =COUNTIFS('Defect log'!$D$4:$D$43,"S4",'Defect log'!$G$4:$G$43,"Open")
B34: ACCEPTANCE | C34: =IF(OR(C24>0,C25>0,C26>0,C29>0,C30>0),"NOT YET MET — see the counts above","ACCEPTANCE CRITERIA MET")
B35: This checks criteria 1 and 2. Criterion 3 — a workaround for every other open defect — is a judgement for the section: record it on the Sign-off sheet.
A37: The criteria being checked (from the form)
B38: 1. Every scenario marked * has passed.
B39: 2. No Severity 1 or Severity 2 defect is still open.
B40: 3. Every other open defect has a workaround the section has agreed and recorded here.
A42: Scenarios failing for any tester, by area
B43: A — Access and sign-in | C43: =COUNTIFS(Results!B10:B47,"A — Access and sign-in",Results!G10:G47,"FAILED")
B44: B — Reading and monitoring a record | C44: =COUNTIFS(Results!B10:B47,"B — Reading and monitoring a record",Results!G10:G47,"FAILED")
B45: C — Capturing a delegation report | C45: =COUNTIFS(Results!B10:B47,"C — Capturing a delegation report",Results!G10:G47,"FAILED")
B46: D — Capturing a resolution and an agreement | C46: =COUNTIFS(Results!B10:B47,"D — Capturing a resolution and an agreement",Results!G10:G47,"FAILED")
B47: E — Moving a record on, and the ATC publication | C47: =COUNTIFS(Results!B10:B47,"E — Moving a record on, and the ATC publication",Results!G10:G47,"FAILED")
...

Sheet Expected behaviour
A1: Expected behaviour — do not log these as defects
A2: Deliberate, and confirmed with the section. Note them in your comments only if they cause a problem for the section's work.
A4: # | B4: Behaviour | C4: What it actually is
A5: 1 | B5: A blocked move may look unblocked | C5: The Referrals tab's Conditions column can show a dash for the report's closing move even though it needs the ATC update. The confirmation page is the authority on whether a move may be taken.
A6: 2 | B6: An agreement's first stage is not reachable | C6: Submitted for tabling on an international agreement has no incoming move, so a record starts at Agreement Tabled – referred to Committee .
A7: 3 | B7: Lists are not paged | C7: Registers, alerts and the timeline show a fixed number of rows without page controls. Use search and the filters to narrow a long list.
A8: 4 | B8: The header search box is decorative | C8: The search box in the page header does not search anything. Use the Search on the page you are working in.
A9: 5 | B9: The report type does not change an export | C9: Choosing Referrals or Activity changes what is previewed on screen, but a workbook, PDF or web-page export always carries the summary, breakdowns, register, activity and referrals. The CSV is the register only.
A10: 6 | B10: A share is fixed once created | C10: A share link's recipients, expiry and message cannot be changed afterwards, and only an administrator can revoke it. It also stops working if the account that created it is removed.
A11: 7 | B11: Email needs configuration | C11: Alert and shared-report email depends on the mail service and the background worker being configured and running. If email does not arrive, the in-app bell is still accurate — raise it with the administrator.
A12: 8 | B12: Detaching keeps the file | C12: Detaching removes the link from the record only; the file stays in SharePoint. Re-uploading the same file name into the same folder becomes a new version.
A13: 9 | B13: Document links expire | C13: A SharePoint address resolved by PWMS is short-lived. Send the record, not the resolved address.
A14: 10 | B14: Reference numbers restart each January | C14: A delegation report's and an agreement's reference begin again at 0001 each year, so the full reference including the year should always be quoted.
A15: 11 | B15: Changing the stage on the edit form | C15: The edit form can move a record's stage without taking a transition. It is an administrator's correction tool: it checks no requirement and records no move. If you used it while testing, say so — it is not a defect.

Sheet Sign-off
A1: Sign-off
A2: Complete alongside the signed printable form
A4: Decision
B5: ☐ | C5: Accept
B6: ☐ | C6: Accept with the workarounds recorded in the Defect log
B7: ☐ | C7: Not accepted — reasons recorded below
A9: Agreed workarounds, and anything carried forward
A15: Overall comments
A23: Signatures
C24: Name and signature | D24: Date
B25: Tested by (tester)
B26: Reviewed by (section leader)
B27: Accepted by (business owner)
A29: Attachments
B30: List the screenshots and files, each named with its scenario ID
B35: By signing, the tester confirms the scenarios were carried out as described and the results recorded are accurate. Return this workbook with the completed form to the section leader.
